File: Tensile-Tests-Data/Dragon Skin FX Pro Slacker.csv
PARAMETER;INFO;;;
Specimen Thickness (mm);3;;;
Specimen Width (mm);6;;;
Specimen Length (mm);33;;;
Specimen Cross-section (cm^2);0.18;;;
Standard;ASTM D412;;;
Type of test;Pull-to-failure;;;
Speed (mm/min);450;;;
Machine;Instron  5569;;;
Load Cell;1 kN - Instron  2525-806;;;
Grippers;Instron 2710-010 ;;;
Strain Measurement;Global;;;
Strain calculation;Derived from the machine crosshead displacement readings;;;
Lab;Univ. Savoie Mont Blanc - SYMME Lab. 7400 Annecy. France;;;
Material supplier;Smooth-On;;;
Material;Dragon Skin FX Pro & Slacker;;;
;;;;
Time (s);True Strain;True Stress (MPa);Engineering Strain;Engineering Stress (MPa)
0.2;0.01828;0.02406;0.018448102;0.023624179
0.5;0.08695;0.00106015;0.090842136;0.000971864
0.6;0.10762;0.00120528;0.113624488;0.001082304
0.7;0.12783;0.00120936;0.136359805;0.00106424
0.8;0.14763;0.00150707;0.159083956;0.001300225
0.9;0.16705;0.00156192;0.181813354;0.00132163
1;0.1861;0.0021887;0.204542709;0.001817038
1.1;0.20479;0.00152047;0.227267312;0.001238907
1.2;0.22315;0.0028003;0.250008061;0.002240226
1.3;0.24116;0.00193633;0.272724655;0.001521405
1.4;0.25886;0.00290363;0.295452429;0.002241402
1.5;0.27625;0.00212113;0.318177367;0.001609139
1.6;0.29335;0.00314747;0.340912028;0.002347261
1.7;0.31015;0.00306377;0.363629643;0.002246776
1.8;0.32668;0.00339742;0.386357772;0.002450608
1.9;0.34295;0.00366213;0.409098305;0.002598917
2;0.35895;0.00360056;0.431825209;0.002514664
2.1;0.37469;0.00395029;0.454540437;0.002715834
2.2;0.39019;0.0040446;0.477261447;0.002737904
2.3;0.40546;0.00462581;0.499992338;0.003083889
2.4;0.4205;0.00440872;0.522722727;0.002895287
2.5;0.43532;0.0048021;0.545457526;0.003107235
2.6;0.44992;0.00480354;0.568186726;0.003063117
2.7;0.46431;0.00477515;0.590916078;0.00300151
2.8;0.47849;0.0055396;0.613635971;0.003432992
2.9;0.49247;0.00572436;0.636353024;0.003498243
3;0.50627;0.00590922;0.659091229;0.003561721
3.1;0.51988;0.00634226;0.681825818;0.003771056
3.2;0.5333;0.00590636;0.704548046;0.003465059
3.3;0.54654;0.00638582;0.727266325;0.003697067
3.4;0.55961;0.00692955;0.749989871;0.003959766
3.5;0.57252;0.00645392;0.772728704;0.00364067
3.6;0.58526;0.00750729;0.795457744;0.004181268
3.7;0.59784;0.00739982;0.818187271;0.004069889
3.8;0.61026;0.00751556;0.840909973;0.004082524
3.9;0.62253;0.00781593;0.863637084;0.004193912
4;0.63465;0.0080562;0.886361799;0.004270761
4.1;0.64663;0.00829554;0.909096322;0.004345271
4.2;0.65846;0.00854792;0.931815047;0.004424813
4.3;0.67016;0.00923384;0.954550024;0.004724279
4.4;0.68172;0.00921021;0.977275723;0.00465803
4.5;0.69315;0.00992737;1.000005639;0.004963671
4.6;0.70445;0.00974251;1.022733875;0.004816506
4.7;0.71562;0.0101957;1.045454471;0.004984565
4.8;0.72667;0.0103153;1.068182082;0.004987617
4.9;0.7376;0.0106444;1.090911301;0.005090795
5;0.74841;0.0113534;1.113636661;0.0053715
5.1;0.75911;0.0110813;1.136374001;0.005186966
5.2;0.76969;0.0111462;1.15909683;0.005162436
5.3;0.78016;0.0116448;1.181821329;0.005337192
5.4;0.79052;0.0119399;1.20454249;0.005416044
5.5;0.80078;0.0120655;1.227277528;0.005417152
5.6;0.81093;0.0128944;1.249999514;0.005730846
5.7;0.82098;0.0127595;1.272726018;0.005614183
5.8;0.83093;0.0128659;1.295452519;0.005604951
5.9;0.84078;0.0135363;1.318174448;0.005839207
6;0.85054;0.0145036;1.340910602;0.006195709
6.1;0.8602;0.0137928;1.363633373;0.005835423
6.2;0.86977;0.0142835;1.386361927;0.005985471
6.3;0.87925;0.0153057;1.40909221;0.006353306
6.4;0.88864;0.0152136;1.431820126;0.006256055
6.5;0.89794;0.0157227;1.454541544;0.006405555
6.6;0.90716;0.016082;1.477277067;0.006491805
6.7;0.91629;0.0163528;1.49999817;0.006541125
6.8;0.92534;0.0171048;1.522725841;0.006780285
6.9;0.93431;0.0174782;1.545456487;0.00686643
7;0.9432;0.0174141;1.56818648;0.006780699
7.1;0.95201;0.0181676;1.590912162;0.007012048
7.2;0.96074;0.0180552;1.613629844;0.006908094
7.3;0.9694;0.0184213;1.636362167;0.006987394
7.4;0.97798;0.0192653;1.659079473;0.007245101
7.5;0.98649;0.0200375;1.681804798;0.007471647
7.6;0.99493;0.0199822;1.704535017;0.007388405
7.7;1.0033;0.0197256;1.727266976;0.007232735
7.8;1.0116;0.0203665;1.749997493;0.007406007
7.9;1.01983;0.0209664;1.772723361;0.007561663
8;1.02799;0.020932;1.795441347;0.007487905
8.1;1.03609;0.0221932;1.818176374;0.007875022
8.2;1.04412;0.0211994;1.840897434;0.007462219
8.3;1.05209;0.0229023;1.863629855;0.007997647
8.4;1.06;0.0231974;1.886370989;0.008036874
8.5;1.06784;0.0230801;1.909089076;0.007933789
8.6;1.07562;0.0237333;1.931810059;0.008095101
8.7;1.08335;0.0247859;1.954560769;0.00838903
8.8;1.09101;0.0244388;1.977279607;0.008208433
8.9;1.09861;0.0250542;1.999993134;0.008351419
9;1.10616;0.0253471;2.022728801;0.008385503
9.1;1.11365;0.0267018;2.04545404;0.008767757
9.2;1.12108;0.0266822;2.068166034;0.008696465
9.3;1.12847;0.0275111;2.090923767;0.008900608
9.4;1.13579;0.0275362;2.113632341;0.008843754
9.5;1.14306;0.0272991;2.13635093;0.008704096
9.6;1.15028;0.0281812;2.159077328;0.008920706
9.7;1.15745;0.0285107;2.181809309;0.008960531
9.8;1.16457;0.0290004;2.204544633;0.009049773
9.9;1.17164;0.0302974;2.227281042;0.009387903
10;1.17866;0.031234;2.250016262;0.009610413
10.1;1.18562;0.0316819;2.272715276;0.009680616
10.2;1.19254;0.0314545;2.295441006;0.009544853
10.3;1.19942;0.032557;2.318191813;0.009811669
10.4;1.20624;0.0324491;2.340899226;0.009712684
10.5;1.21302;0.0342249;2.363627484;0.010174997
10.6;1.21976;0.033816;2.386374906;0.0099859
10.7;1.22645;0.0346347;2.409105704;0.010159468
10.8;1.23309;0.0351176;2.431817486;0.010232945
10.9;1.23969;0.0361862;2.454542391;0.010474962
11;1.24625;0.0365476;2.477278682;0.010510403
11.1;1.25276;0.0377486;2.49998961;0.010785346
11.2;1.25924;0.0379362;2.522743185;0.010768937
11.3;1.26567;0.0378328;2.545467404;0.010670751
11.4;1.27206;0.0389003;2.568195479;0.010901953
11.5;1.2784;0.0386373;2.590889703;0.010759813
11.6;1.28471;0.0397509;2.613619855;0.011000299
11.7;1.29098;0.0397972;2.636348432;0.010944276
11.8;1.29722;0.0416242;2.659110189;0.011375498
11.9;1.30341;0.0424307;2.681830327;0.01152435
12;1.30956;0.0421523;2.704543354;0.011378541
12.1;1.31568;0.0421821;2.727284677;0.011317112
12.2;1.32175;0.0438102;2.7499781;0.011682788
12.3;1.3278;0.0451141;2.772734236;0.011957932
12.4;1.3338;0.0456376;2.795438686;0.012024328
12.5;1.33977;0.0453898;2.818165226;0.011887856
12.6;1.34571;0.0459448;2.840912621;0.011961949
12.7;1.35161;0.0471957;2.863640988;0.012215343
12.8;1.35747;0.0485362;2.886348392;0.012488896
12.9;1.3633;0.0489312;2.909071978;0.012517344
13;1.3691;0.0502711;2.931810473;0.012785738
13.1;1.37487;0.0497628;2.954562596;0.012583642
13.2;1.3806;0.0506685;2.977287284;0.012739462
13.3;1.38629;0.0517202;2.999982556;0.012930106
13.4;1.39196;0.0518582;3.022726876;0.012891305
13.5;1.39759;0.0527609;3.045438702;0.013042071
13.6;1.4032;0.0541853;3.068197392;0.013319241
13.7;1.40877;0.0556511;3.090920476;0.013603564
13.8;1.41431;0.0561409;3.11364707;0.013647476
13.9;1.41982;0.055749;3.136375826;0.013477741
14;1.4253;0.0558157;3.159105387;0.013420122
14.1;1.43075;0.0578649;3.181834392;0.013837205
14.2;1.43617;0.0577693;3.204561469;0.013739673
14.3;1.44156;0.0602147;3.227285241;0.014244295
14.4;1.44692;0.0600099;3.250004323;0.014119962
14.5;1.45225;0.0605497;3.272717322;0.014171239
14.6;1.45756;0.0617969;3.295465795;0.014386542
14.7;1.46283;0.0634293;3.318162653;0.014688956
14.8;1.46808;0.0636494;3.340892621;0.014662745
14.9;1.47331;0.0650345;3.363654961;0.014903676
15;1.4785;0.0652202;3.386361202;0.014868862
15.1;1.48367;0.0667803;3.409097412;0.015146025
15.2;1.48881;0.0671335;3.431818516;0.015148071
15.3;1.49392;0.0679281;3.454523069;0.015249242
15.4;1.49901;0.0693608;3.477254394;0.015491816
15.5;1.50408;0.0704251;3.500011715;0.015649981
15.6;1.50912;0.0718126;3.522749023;0.015878086
15.7;1.51413;0.0738164;3.545464852;0.016239571
15.8;1.51912;0.0736597;3.568203407;0.016124435
15.9;1.52408;0.0740316;3.590917981;0.016125664
16;1.52902;0.0750689;3.613653226;0.016271032
16.1;1.53393;0.0770603;3.636361968;0.016620855
16.2;1.53882;0.0777424;3.659089301;0.016686179
16.3;1.54369;0.0783907;3.681834405;0.016743587
16.4;1.54853;0.0794342;3.704549409;0.01688455
16.5;1.55335;0.0805033;3.727280074;0.017029518
16.6;1.55814;0.0795533;3.749978064;0.016748141
16.7;1.56292;0.0828383;3.772737311;0.01735656
16.8;1.56767;0.0834903;3.795461741;0.017410273
16.9;1.5724;0.085115;3.818198004;0.017665318
17;1.5771;0.0857652;3.840896835;0.0177168
17.1;1.58179;0.0868786;3.863653965;0.017862825
17.2;1.58645;0.0879132;3.886371483;0.01799151
17.3;1.59109;0.0890617;3.909096929;0.018142176
17.4;1.59571;0.0899199;3.931829428;0.018232565
17.5;1.60031;0.0905353;3.954568102;0.018273096
17.6;1.60488;0.0933098;3.977262295;0.018747214
17.7;1.60944;0.0934601;4.000010438;0.018691981
17.8;1.61397;0.0949437;4.022711865;0.018902876
17.9;1.61849;0.096084;4.045465908;0.019043633
18;1.62298;0.0980806;4.068170985;0.019352267
18.1;1.62746;0.0992766;4.090927327;0.019500691
18.2;1.63191;0.100987;4.113632435;0.019748584
18.3;1.63635;0.100923;4.136387442;0.019648635
18.4;1.64076;0.102267;4.15908893;0.019822686
18.5;1.64516;0.102851;4.181838935;0.019848359
18.6;1.64953;0.104222;4.204533122;0.020025235
18.7;1.65389;0.106729;4.227274426;0.020417715
18.8;1.65823;0.107509;4.250010098;0.020477865
18.9;1.66255;0.109029;4.272739201;0.020677867
19;1.66685;0.110005;4.295460796;0.020773452
19.1;1.67113;0.111296;4.31817394;0.020927484
19.2;1.6754;0.112962;4.340931094;0.021150245
19.3;1.67964;0.114193;4.363624719;0.021290267
19.4;1.68387;0.11614;4.386360904;0.021561867
19.5;1.68808;0.117715;4.409085285;0.02176246
19.6;1.69227;0.11855;4.4317969;0.02182519
19.7;1.69645;0.120436;4.45454933;0.022079918
19.8;1.70061;0.12098;4.477287518;0.022087575
19.9;1.70475;0.124054;4.500010493;0.02255523
20;1.70887;0.124968;4.52271728;0.022627992
20.1;1.71298;0.126358;4.545462357;0.022785837
20.2;1.71707;0.126183;4.568189744;0.022661404
20.3;1.72114;0.128973;4.590898457;0.023068385
20.4;1.7252;0.12968;4.613643646;0.023100861
20.5;1.72924;0.132777;4.63636864;0.023557189
20.6;1.73326;0.133818;4.659072446;0.023646631
20.7;1.73727;0.133739;4.681810887;0.023538094
20.8;1.74126;0.13681;4.7045266;0.023982709
20.9;1.74524;0.137396;4.727275857;0.023989765
21;1.7492;0.139115;4.750000835;0.02419391
21.1;1.75314;0.139654;4.772700527;0.024192144
21.2;1.75707;0.142978;4.795431878;0.02467081
21.3;1.76099;0.143929;4.818194557;0.024737743
21.4;1.76489;0.145163;4.84092982;0.024852721
21.5;1.76877;0.147602;4.863636651;0.025172433
21.6;1.77264;0.149543;4.886372891;0.025404948
21.7;1.77649;0.150557;4.909079108;0.025478928
21.8;1.78033;0.15449;4.931813594;0.026044311
21.9;1.78415;0.156012;4.954516457;0.026200616
22;1.78796;0.156689;4.977246438;0.026214245
22.1;1.79176;0.157296;5.000003185;0.026215986
22.2;1.79554;0.158459;5.022726116;0.026310179
22.3;1.79931;0.161282;5.045474647;0.026678137
22.4;1.80306;0.162919;5.068187738;0.026848049
22.5;1.8068;0.165779;5.090925253;0.027217376
22.6;1.81052;0.166657;5.113625691;0.027259929
22.7;1.81423;0.167495;5.136349369;0.027295545
22.8;1.81793;0.169384;5.159095917;0.027501439
22.9;1.82161;0.171708;5.181803145;0.027776362
23;1.82528;0.172749;5.204532045;0.02784239
23.1;1.82894;0.173938;5.22728224;0.027931607
23.2;1.83258;0.176219;5.249990852;0.028195081
23.3;1.83621;0.178253;5.272719546;0.02841718
23.4;1.83983;0.1805;5.295467941;0.028671419
23.5;1.84343;0.181453;5.318172469;0.028719222
23.6;1.84702;0.184471;5.340895471;0.029092263
23.7;1.8506;0.186236;5.363636559;0.029265656
23.8;1.85417;0.188335;5.386395342;0.029490032
23.9;1.85772;0.188165;5.409107335;0.029359003
24;1.86126;0.192311;5.431835781;0.029899862
24.1;1.86478;0.192811;5.454515736;0.029872264
24.2;1.8683;0.19549;5.477275666;0.030180899
24.3;1.8718;0.19929;5.49998585;0.030660067
24.4;1.87529;0.201944;5.522710432;0.030960136
24.5;1.87877;0.202484;5.545449007;0.030935082
24.6;1.88224;0.204346;5.568201167;0.03111141
24.7;1.88569;0.205935;5.590900595;0.031245351
24.8;1.88913;0.20879;5.613612335;0.031569737
24.9;1.89256;0.212077;5.636335974;0.031956941
25;1.89598;0.213058;5.659071098;0.031995153
25.1;1.89939;0.214907;5.68181729;0.032162957
25.2;1.90279;0.21454;5.704574134;0.03199905
25.3;1.90617;0.218351;5.727273935;0.032457575
25.4;1.90954;0.221198;5.749983092;0.032770156
25.5;1.9129;0.223239;5.77270118;0.03296159
25.6;1.91625;0.227682;5.795427775;0.033505175
25.7;1.91959;0.22849;5.81816245;0.033511962
25.8;1.92292;0.229879;5.840904775;0.033603596
25.9;1.92624;0.231215;5.863654323;0.033686865
26;1.92954;0.234983;5.886341796;0.034123052
26.1;1.93284;0.238266;5.909104261;0.034485802
26.2;1.93612;0.240947;5.931803329;0.034759642
26.3;1.9394;0.242719;5.954576972;0.034900613
26.4;1.94266;0.243555;5.977285889;0.03490684
26.5;1.94591;0.245241;5.999998957;0.035034434
26.6;1.94915;0.249074;6.022715735;0.035466906
26.7;1.95238;0.251741;6.045435779;0.035731076
26.8;1.9556;0.254659;6.068158647;0.036029044
26.9;1.95881;0.25709;6.090883891;0.036256411
27;1.96201;0.258357;6.113611063;0.036318685
27.1;1.9652;0.260735;6.136339715;0.036536237
27.2;1.96838;0.264333;6.159069397;0.036922816
27.3;1.97155;0.267992;6.181799655;0.037315438
27.4;1.97471;0.269937;6.204530037;0.037467676
27.5;1.97786;0.272083;6.227260088;0.03764677
27.6;1.981;0.273333;6.249989351;0.037701159
27.7;1.98413;0.275238;6.272717368;0.037845277
27.8;1.98725;0.279974;6.295443681;0.038376556
27.9;1.99036;0.282573;6.318167829;0.038612533
28;1.99346;0.286533;6.340889349;0.039032464
28.1;1.99655;0.2893;6.363607779;0.039287807
28.2;1.99964;0.289117;6.386396517;0.03914182
28.3;2.00271;0.293718;6.409107598;0.039642831
28.4;2.00577;0.296283;6.431814191;0.039866847
28.5;2.00882;0.297772;6.454515827;0.039945183
28.6;2.01187;0.301862;6.477286808;0.040370526
28.7;2.0149;0.30445;6.499977346;0.040593456
28.8;2.01793;0.307157;6.52273674;0.040830486
28.9;2.02094;0.309348;6.545414291;0.040998146
29;2.02395;0.312012;6.568160203;0.041226929
29.1;2.02695;0.315997;6.590898774;0.041628404
29.2;2.02994;0.318485;6.613629527;0.041830903
29.3;2.03292;0.324294;6.636351983;0.042467136
29.4;2.03589;0.324698;6.659065661;0.042393944
29.5;2.03886;0.327585;6.6818469;0.042644042
29.6;2.04181;0.32955;6.704541807;0.042773472
29.7;2.04476;0.333125;6.727303762;0.043110121
29.8;2.04769;0.336191;6.749977964;0.043379607
29.9;2.05062;0.341392;6.772718698;0.043921826
30;2.05354;0.343762;6.795448206;0.044097785
30.1;2.05645;0.344365;6.818165998;0.044046775
30.2;2.05935;0.344909;6.840871587;0.043988605
30.3;2.06225;0.352104;6.863643117;0.044776193
30.4;2.06514;0.352948;6.886401917;0.044753996
30.5;2.06801;0.360556;6.909068401;0.04558767
30.6;2.07088;0.362396;6.931800032;0.045688999
30.7;2.07374;0.363866;6.95451745;0.045743315
30.8;2.0766;0.368412;6.977299933;0.046182543
30.9;2.07944;0.369698;6.999987667;0.046212321
31;2.08228;0.374485;7.022739924;0.046677943
31.1;2.08511;0.377908;7.045476435;0.046971488
31.2;2.08793;0.380218;7.068196699;0.047125524
31.3;2.09074;0.383611;7.090900216;0.047412648
31.4;2.09355;0.386473;7.113667619;0.047632343
31.5;2.09634;0.390108;7.136336359;0.047946395
31.6;2.09913;0.392882;7.159068434;0.048152801
31.7;2.10191;0.395186;7.181782202;0.048300724
31.8;2.10469;0.399741;7.204559202;0.048721813
31.9;2.10745;0.402591;7.227235064;0.048933937
32;2.11021;0.405982;7.249973597;0.049210097
32.1;2.11296;0.408568;7.272692248;0.04938755
32.2;2.11571;0.41266;7.295473462;0.049745202
32.3;2.11844;0.417302;7.318151045;0.050167639
32.4;2.12117;0.42358;7.340890623;0.050783546
32.5;2.12389;0.424462;7.363608728;0.050751059
32.6;2.12661;0.424421;7.386388711;0.050608315
32.7;2.12931;0.42876;7.409062556;0.050987848
32.8;2.13201;0.432335;7.431797704;0.051274356
32.9;2.1347;0.438112;7.454509773;0.051819918
33;2.13739;0.443679;7.477283021;0.052337406
33.1;2.14007;0.447402;7.50003261;0.052635327
33.2;2.14274;0.447054;7.522758022;0.052454147
33.3;2.1454;0.451893;7.545458737;0.05288107
33.4;2.14806;0.457396;7.568219916;0.05338285
33.5;2.1507;0.459145;7.590869902;0.053445694
33.6;2.15335;0.462245;7.613665898;0.053664143
33.7;2.15598;0.469055;7.636349656;0.054311719
33.8;2.15861;0.472378;7.65909315;0.054552826
33.9;2.16123;0.47405;7.68180972;0.054602671
34;2.16385;0.480641;7.704585885;0.055216986
34.1;2.16645;0.484876;7.727247255;0.05555887
34.2;2.16905;0.486911;7.749967622;0.055647177
34.3;2.17165;0.492073;7.772747138;0.056091096
34.4;2.17424;0.495916;7.795498003;0.056382936
34.5;2.17682;0.499279;7.818219686;0.056619025
34.6;2.17939;0.501743;7.840911657;0.056752405
34.7;2.18196;0.504603;7.863662022;0.056929404
34.8;2.18452;0.510702;7.886382066;0.057470183
34.9;2.18707;0.51756;7.909071257;0.058093598
35;2.18962;0.517953;7.931818379;0.057989648
35.1;2.19216;0.524406;7.954534034;0.058563181
35.2;2.1947;0.524435;7.977307461;0.05841785
35.3;2.19722;0.528477;7.999958804;0.058719935
35.4;2.19975;0.53444;8.022757528;0.059232446
35.5;2.20226;0.540183;8.045433095;0.059718865
35.6;2.20477;0.543144;8.06816565;0.059895686
35.7;2.20728;0.548162;8.090955335;0.060297513
35.8;2.20977;0.549527;8.113620019;0.060297335
35.9;2.21226;0.555172;8.136341209;0.060765244
36;2.21475;0.560133;8.159119046;0.061155772
36.1;2.21722;0.564019;8.181770032;0.061428134
36.2;2.2197;0.566441;8.204569081;0.061539111
36.3;2.22216;0.57286;8.227240195;0.062083569
36.4;2.22462;0.575645;8.249967148;0.062232113
36.5;2.22708;0.580889;8.272750079;0.062644738
36.6;2.22953;0.586332;8.295496169;0.063076999
36.7;2.23197;0.591133;8.318204873;0.063438506
36.8;2.2344;0.597265;8.340875645;0.063941008
36.9;2.23683;0.601743;8.363601574;0.064264054
37;2.23926;0.603995;8.386382794;0.064348004
37.1;2.24168;0.610195;8.409125347;0.064851405
37.2;2.24409;0.613228;8.431828686;0.065016872
37.3;2.2465;0.61847;8.454586806;0.06541481
37.4;2.2489;0.623584;8.477305065;0.065797608
37.5;2.25129;0.627829;8.499982913;0.066087382
37.6;2.25368;0.631354;8.522715026;0.066299789
37.7;2.25606;0.638585;8.54540608;0.066899721
37.8;2.25844;0.641124;8.568151202;0.067006048
37.9;2.26082;0.647032;8.590950523;0.067462761
38;2.26318;0.651275;8.613611896;0.06774509
38.1;2.26554;0.65701;8.636326813;0.068180544
38.2;2.2679;0.662632;8.659095401;0.068601869
38.3;2.27025;0.665523;8.681820967;0.068739445
38.4;2.27259;0.669072;8.704502955;0.068944489
38.5;2.27493;0.676599;8.727238082;0.069557154
38.6;2.27727;0.680296;8.750026471;0.069773759
38.7;2.2796;0.687739;8.772770519;0.070372982
38.8;2.28192;0.692689;8.795469668;0.070715241
38.9;2.28424;0.694917;8.818221539;0.070778297
39;2.28655;0.701793;8.840927847;0.071313702
39.1;2.28885;0.707547;8.86358803;0.071733227
39.2;2.29116;0.711098;8.886399255;0.071926895
39.3;2.29345;0.720059;8.909065052;0.072666694
39.4;2.29574;0.721887;8.931782813;0.072684533
39.5;2.29803;0.72473;8.954552657;0.072803874
39.6;2.30031;0.730361;8.977274931;0.073202453
39.7;2.30258;0.737518;8.99994907;0.073752176
39.8;2.30486;0.74065;9.022774966;0.073896701
39.9;2.30712;0.746817;9.045452053;0.074343792
40;2.30938;0.752401;9.068180448;0.074730584
40.1;2.31163;0.756908;9.090859358;0.075009271
40.2;2.31388;0.761362;9.113589353;0.075281087
40.3;2.31613;0.767823;9.136370548;0.075749303
40.4;2.31837;0.771071;9.159101467;0.075899527
40.5;2.3206;0.778204;9.181781543;0.076431025
40.6;2.32283;0.781165;9.204512251;0.07655094
40.7;2.32506;0.787144;9.227293705;0.076965033
40.8;2.32728;0.789208;9.250023518;0.076995726
40.9;2.32949;0.795996;9.272701119;0.077486534
41;2.3317;0.8033;9.295428894;0.078024918
41.1;2.33391;0.807148;9.318206952;0.078225607
41.2;2.33611;0.808183;9.340931996;0.078153787
41.3;2.3383;0.81163;9.363603453;0.078315424
41.4;2.34049;0.813914;9.386324615;0.078364006
41.5;2.34268;0.819411;9.409095591;0.078720672
41.6;2.34486;0.825564;9.431812172;0.079139078
41.7;2.34704;0.830729;9.454578328;0.079460785
41.8;2.34921;0.841763;9.477289396;0.080341677
41.9;2.35138;0.843291;9.5000498;0.080313048
42;2.35354;0.848342;9.52275442;0.080619766
42.1;2.35569;0.852308;9.54540268;0.080822708
42.2;2.35785;0.856224;9.568205368;0.081018865
42.3;2.36;0.864276;9.590951452;0.081605133
42.4;2.36214;0.871914;9.613640357;0.082150325
42.5;2.36428;0.876607;9.636377868;0.082415932
42.6;2.36641;0.883848;9.659057498;0.082919902
42.7;2.36854;0.886232;9.681785487;0.082966654
42.8;2.37067;0.891989;9.704561939;0.083327931
42.9;2.37279;0.898952;9.727279682;0.083800556
43;2.37491;0.905717;9.750045638;0.084252386
43.1;2.37702;0.910629;9.772752182;0.084530767
43.2;2.37913;0.915245;9.795506686;0.08478018
43.3;2.38123;0.921732;9.818201071;0.085201966
43.4;2.38333;0.928086;9.840943164;0.085609341
43.5;2.38542;0.93354;9.863624429;0.085932647
43.6;2.38751;0.941794;9.886353147;0.086511432
43.7;2.3896;0.945408;9.909129418;0.086662094
43.8;2.39168;0.953568;9.931844023;0.087228467
43.9;2.39375;0.96022;9.954496377;0.08765533
44;2.39583;0.965082;9.977305443;0.087916111
44.1;2.39789;0.969966;9.999941999;0.088179192
44.2;2.39996;0.977821;10.02273546;0.088709468
44.3;2.40202;0.986289;10.0454657;0.089293564
44.4;2.40407;0.991789;10.06813213;0.089607622
44.5;2.40613;0.99681;10.09095598;0.089875931
44.6;2.40817;1.00071;10.11360463;0.090043693
44.7;2.41022;1.0092;10.13641089;0.090621656
44.8;2.41225;1.01415;10.15904076;0.090881467
44.9;2.41429;1.02495;10.18182844;0.091662111
45;2.41632;1.03103;10.20455061;0.092018862
45.1;2.41835;1.03517;10.22731895;0.092200997
45.2;2.42037;1.03909;10.25002105;0.092363383
45.3;2.42239;1.04569;10.27276906;0.092762479
45.4;2.4244;1.057;10.29545012;0.093577501
45.5;2.42641;1.06314;10.3181768;0.09393209
45.6;2.42842;1.0717;10.34094922;0.094498263
45.7;2.43042;1.07318;10.36365381;0.094439695
45.8;2.43242;1.0804;10.38640386;0.094885094
45.9;2.43441;1.08559;10.40908537;0.095151361
46;2.4364;1.09369;10.43181205;0.095670747
46.1;2.43839;1.10487;10.45458401;0.09645658
46.2;2.44037;1.10791;10.47728655;0.096530656
46.3;2.44235;1.11127;10.50003409;0.096631887
46.4;2.44432;1.12046;10.52271149;0.097239265
46.5;2.44629;1.12892;10.54543361;0.09778065
46.6;2.44826;1.13489;10.56820053;0.098104281
46.7;2.45022;1.14145;10.59089644;0.098478147
46.8;2.45218;1.14972;10.61363687;0.098997413
46.9;2.45414;1.15838;10.63642192;0.099547783
47;2.45609;1.16211;10.65913508;0.099673774
47.1;2.45803;1.16919;10.68177576;0.100086667
47.2;2.45998;1.17486;10.70457745;0.100376114
47.3;2.46192;1.18191;10.72730637;0.100782734
47.4;2.46385;1.19012;10.74996192;0.101287137
47.5;2.46579;1.19798;10.77277897;0.101758472
47.6;2.46771;1.20439;10.79540442;0.102106715
47.7;2.46964;1.21199;10.81819154;0.102552916
47.8;2.47156;1.21952;10.84090426;0.102992134
47.9;2.47348;1.22393;10.86366064;0.103166302
48;2.47539;1.23225;10.88634188;0.103669406
48.1;2.4773;1.24122;10.90906649;0.104224794
48.2;2.47921;1.25041;10.93183454;0.104796123
48.3;2.48111;1.2542;10.95452658;0.104914234
48.4;2.48301;1.26499;10.97726177;0.10561596
48.5;2.48491;1.27203;11.0000402;0.106002145
48.6;2.4868;1.27615;11.02274172;0.106144674
48.7;2.48869;1.28296;11.04548619;0.106509607
48.8;2.49057;1.29236;11.06815301;0.107088467
48.9;2.49245;1.29473;11.09086248;0.107083345
49;2.49433;1.30494;11.11361468;0.107725071
49.1;2.49621;1.31163;11.13640969;0.108073972
49.2;2.49808;1.31656;11.15912601;0.108277519
49.3;2.49994;1.33337;11.18176303;0.109456242
49.4;2.50181;1.33326;11.20456424;0.109242737
49.5;2.50367;1.34575;11.22728586;0.11006122
49.6;2.50553;1.35106;11.25004977;0.110290164
49.7;2.50738;1.35826;11.27273334;0.110672982
49.8;2.50923;1.36388;11.29545891;0.110925506
49.9;2.51108;1.37527;11.31822656;0.11164513
50;2.51292;1.38549;11.34091297;0.112268031
50.1;2.51476;1.38778;11.36364115;0.112246868
50.2;2.5166;1.39803;11.38641119;0.112868044
50.3;2.51843;1.40702;11.40909908;0.113386152
50.4;2.52026;1.41702;11.43182852;0.113983232
50.5;2.52209;1.42258;11.45459959;0.114221255
50.6;2.52391;1.4311;11.47728761;0.114696402
50.7;2.52573;1.43809;11.50001695;0.115047044
50.8;2.52754;1.4445;11.52266246;0.115350869
50.9;2.52936;1.45429;11.54547446;0.115921483
51;2.53117;1.46387;11.56820233;0.116474096
51.1;2.53298;1.47248;11.59097138;0.116947291
51.2;2.53478;1.4826;11.61365554;0.117539281
51.3;2.53658;1.48883;11.63638056;0.117820921
51.4;2.53838;1.49681;11.65914653;0.118239409
51.5;2.54017;1.50646;11.6818267;0.118788881
51.6;2.54196;1.51736;11.7045475;0.119434399
51.7;2.54375;1.52424;11.727309;0.119761373
51.8;2.54553;1.53267;11.74998379;0.120209565
51.9;2.54731;1.542;11.77269897;0.120726246
52;2.54909;1.54875;11.79545462;0.121039076
52.1;2.55086;1.55577;11.81812263;0.121372688
52.2;2.55264;1.56851;11.84095921;0.122148975
52.3;2.5544;1.57863;11.86357919;0.122720899
52.4;2.55617;1.5896;11.88636789;0.123355162
52.5;2.55793;1.59781;11.90906787;0.123774235
52.6;2.55969;1.60409;11.93180783;0.124042208
52.7;2.56145;1.61217;11.95458786;0.124447803
52.8;2.5632;1.62345;11.97727823;0.125099422
52.9;2.56495;1.62912;12.00000835;0.125316843
53;2.5667;1.6416;12.02277829;0.126056051
53.1;2.56844;1.65062;12.04545765;0.126528332
53.2;2.57018;1.65724;12.0681765;0.126814939
53.3;2.57192;1.66732;12.09093492;0.127364471
53.4;2.57365;1.67375;12.11360184;0.127634651
53.5;2.57538;1.68452;12.13630801;0.128233899
53.6;2.57711;1.6936;12.15905349;0.128702266
53.7;2.57884;1.7058;12.18183835;0.129405319
53.8;2.58056;1.71677;12.20453063;0.130013709
53.9;2.58228;1.723;12.22726196;0.130261274
54;2.584;1.73067;12.25003243;0.130616284
54.1;2.58571;1.74505;12.27270937;0.131476547
54.2;2.58742;1.74757;12.29542512;0.131441453
54.3;2.58913;1.76221;12.31817975;0.13231613
54.4;2.59084;1.77149;12.34097332;0.132785664
54.5;2.59254;1.78056;12.36367226;0.133238826
54.6;2.59424;1.79047;12.38640982;0.133752815
54.7;2.59593;1.79954;12.40905198;0.134203373
54.8;2.59763;1.81357;12.43186676;0.135019952
54.9;2.59932;1.81991;12.45458581;0.135263175
55;2.60101;1.82948;12.47734328;0.135744854
55.1;2.60269;1.83594;12.50000425;0.135995513
55.2;2.60437;1.85001;12.52270332;0.136807705
55.3;2.60605;1.86209;12.54544055;0.137469874
55.4;2.60773;1.86966;12.56821602;0.13779704
55.5;2.6094;1.88199;12.59089387;0.138474336
55.6;2.61107;1.89637;12.61360962;0.139299572
55.7;2.61274;1.90046;12.63636335;0.13936707
55.8;2.61441;1.91078;12.6591551;0.139890058
55.9;2.61607;1.91816;12.68184813;0.140197434
56;2.61773;1.92964;12.70457886;0.140802576
56.1;2.61938;1.94021;12.72721008;0.141340446
56.2;2.62104;1.95213;12.75001617;0.141972924
56.3;2.62269;1.96185;12.77272242;0.142444605
56.4;2.62434;1.96968;12.79546617;0.142777343
56.5;2.62599;1.97956;12.81824748;0.143256951
56.6;2.62763;1.99528;12.840928;0.144157964
56.7;2.62927;2.00173;12.86364575;0.144386984
56.8;2.63091;2.01502;12.88640078;0.145107435
56.9;2.63254;2.027;12.90905407;0.145732412
57;2.63418;2.03399;12.93188363;0.145995334
57.1;2.63581;2.04705;12.95461112;0.146693447
57.2;2.63743;2.05689;12.97723591;0.147159997
57.3;2.63906;2.06904;13.00003739;0.147788177
57.4;2.64068;2.0808;13.02273583;0.148387592
57.5;2.6423;2.09128;13.04547107;0.148893547
57.6;2.64392;2.10125;13.06824317;0.149361223
57.7;2.64553;2.10732;13.09091129;0.149551719
57.8;2.64714;2.11838;13.11361593;0.150094775
57.9;2.64875;2.1357;13.13635715;0.151078526
58;2.65036;2.14639;13.15913502;0.151590475
58.1;2.65196;2.15267;13.18180777;0.151790945
58.2;2.65356;2.16783;13.20451682;0.15261554
58.3;2.65516;2.17123;13.22726224;0.152610528
58.4;2.65676;2.18455;13.25004408;0.15330128
58.5;2.65835;2.19924;13.27271967;0.154086961
58.6;2.65994;2.20677;13.29543135;0.154368899
58.7;2.66153;2.21486;13.31817916;0.154688664
58.8;2.66312;2.23071;13.34096318;0.15554813
58.9;2.6647;2.24019;13.36363981;0.155962558
59;2.66628;2.25007;13.3863523;0.156403093
59.1;2.66786;2.26369;13.4091007;0.157101407
59.2;2.66944;2.27417;13.43188507;0.157579553
59.3;2.67101;2.28627;13.45456093;0.158169453
59.4;2.67258;2.29956;13.47727241;0.158839313
59.5;2.67415;2.30383;13.50001958;0.158884613
59.6;2.67571;2.3213;13.52265727;0.159839894
59.7;2.67728;2.32806;13.54547575;0.160053892
59.8;2.67884;2.34321;13.5681844;0.16084434
59.9;2.6804;2.35687;13.5909285;0.161529816
60;2.68196;2.36671;13.61370811;0.161951367
60.1;2.68351;2.37683;13.63637692;0.162391964
60.2;2.68506;2.3829;13.6590809;0.16255453
60.3;2.68661;2.39984;13.68182009;0.163456573
60.4;2.68816;2.41482;13.70459456;0.164222141
60.5;2.6897;2.42609;13.72725708;0.164734681
60.6;2.69124;2.43468;13.74995453;0.16506356
60.7;2.69278;2.4463;13.77268696;0.165596144
60.8;2.69432;2.46155;13.79545442;0.166372044
60.9;2.69585;2.47046;13.81810879;0.166718981
61;2.69739;2.48014;13.84094626;0.167114681
61.1;2.69892;2.49531;13.86367029;0.1678798
61.2;2.70045;2.50794;13.88642911;0.168471564
61.3;2.70197;2.51919;13.90907369;0.168970256
61.4;2.70349;2.52992;13.93175271;0.169432219
61.5;2.70502;2.54394;13.95461578;0.170110689
61.6;2.70653;2.55446;13.97721431;0.170556416
61.7;2.70805;2.56576;13.99999698;0.171050701
61.8;2.70956;2.5815;14.02266409;0.17184036
61.9;2.71108;2.58923;14.0455159;0.172093135
62;2.71259;2.59732;14.06825179;0.172370361
62.1;2.71409;2.61438;14.09087113;0.173242484
62.2;2.7156;2.6249;14.11367556;0.173677144
62.3;2.7171;2.63873;14.13636308;0.174330517
62.4;2.7186;2.65206;14.15908466;0.174948558
62.5;2.7201;2.66863;14.18184035;0.175777767
62.6;2.72159;2.67765;14.20447816;0.1761093
62.7;2.72309;2.68947;14.22730199;0.176621571
62.8;2.72458;2.7027;14.25000758;0.177226141
62.9;2.72607;2.71666;14.27274703;0.177876318
63;2.72756;2.72616;14.29552038;0.178232576
63.1;2.72904;2.74095;14.31817451;0.178934507
63.2;2.73052;2.75144;14.34086219;0.179353674
63.3;2.732;2.76312;14.36358348;0.179848666
63.4;2.73348;2.77629;14.38633842;0.180438641
63.5;2.73496;2.78683;14.40912706;0.1808558
63.6;2.73643;2.8026;14.43179513;0.181612053
63.7;2.7379;2.81344;14.45449655;0.182046694
63.8;2.73937;2.82792;14.47723137;0.182714849
63.9;2.74084;2.83903;14.49999963;0.18316323
64;2.7423;2.85113;14.52264616;0.183675513
64.1;2.74377;2.85812;14.54548123;0.183855357
64.2;2.74523;2.87956;14.56819421;0.184964291
64.3;2.74669;2.89525;14.59094037;0.185700794
64.4;2.74814;2.90599;14.61356363;0.186119586
64.5;2.7496;2.917;14.63637608;0.186552177
64.6;2.75105;2.92745;14.65906527;0.186949218
64.7;2.7525;2.94573;14.68178739;0.187844021
64.8;2.75395;2.95634;14.70454247;0.188247445
64.9;2.7554;2.96513;14.72733058;0.188533584
65;2.75684;2.98646;14.74999425;0.189616577
65.1;2.75828;2.99629;14.77269058;0.189966955
65.2;2.75972;3.0106;14.79541961;0.190599558
65.3;2.76116;3.02041;14.8181814;0.190945465
65.4;2.7626;3.03326;14.84097599;0.191481889
65.5;2.76403;3.05203;14.86364479;0.192391474
65.6;2.76546;3.06635;14.88634603;0.193017954
65.7;2.76689;3.073;14.90907975;0.193160135
65.8;2.76832;3.08909;14.93184601;0.193894041
65.9;2.76974;3.1003;14.9544853;0.19432153
66;2.77117;3.11544;14.97731654;0.194991443
66.1;2.77259;3.1276;15.00002044;0.19547475
66.2;2.77401;3.14159;15.02275661;0.196070506
66.3;2.77543;3.15447;15.04552509;0.196595
66.4;2.77684;3.16358;15.06816524;0.196884956
66.5;2.77825;3.17745;15.09083733;0.197469525
66.6;2.77967;3.19006;15.11370255;0.197971881
66.7;2.78108;3.20601;15.13643889;0.198681383
66.8;2.78248;3.22096;15.15904573;0.199328602
66.9;2.78389;3.23377;15.18184606;0.199839375
67;2.78529;3.24864;15.20451651;0.200477441
67.1;2.78669;3.26281;15.22721872;0.201070193
67.2;2.78809;3.27627;15.24995273;0.201617202
67.3;2.78949;3.29068;15.2727186;0.202220666
67.4;2.79089;3.30598;15.29551636;0.202876664
67.5;2.79228;3.32017;15.31818288;0.203464444
67.6;2.79367;3.32963;15.34088092;0.203760741
67.7;2.79506;3.34089;15.36361054;0.204165822
67.8;2.79645;3.35523;15.38637177;0.204757346
67.9;2.79784;3.37199;15.40916467;0.205494312
68;2.79922;3.38192;15.43182495;0.20581524
68.1;2.8006;3.40312;15.45451652;0.206819811
68.2;2.80198;3.41707;15.47723943;0.207381219
68.3;2.80336;3.42877;15.49999372;0.207804322
68.4;2.80474;3.44056;15.52277942;0.20823131
68.5;2.80611;3.45572;15.54543115;0.208862493
68.6;2.80748;3.46821;15.56811392;0.209330405
68.7;2.80885;3.48194;15.59082779;0.209871385
68.8;2.81022;3.49547;15.6135728;0.210398452
68.9;2.81159;3.51045;15.636349;0.211010841
69;2.81296;3.52167;15.65915641;0.211395458
69.1;2.81432;3.53968;15.68182828;0.212187773
69.2;2.81568;3.55385;15.704531;0.212747667
69.3;2.81704;3.56959;15.72726462;0.213399506
69.4;2.8184;3.58132;15.75002917;0.213809777
69.5;2.81975;3.59079;15.77265698;0.214085938
69.6;2.82111;3.60892;15.79548332;0.214874436
69.7;2.82246;3.62268;15.81817253;0.215402714
69.8;2.82381;3.63886;15.8408924;0.216072873
69.9;2.82516;3.65071;15.86364295;0.216484066
70;2.82651;3.66454;15.88642425;0.217011011
70.1;2.82785;3.67956;15.90906722;0.217608692
70.2;2.82919;3.69268;15.93174056;0.218092168
70.3;2.83054;3.70774;15.95461384;0.218686196
70.4;2.83188;3.72332;15.97734826;0.219311046
70.5;2.83321;3.73562;15.99994315;0.219743088
70.6;2.83455;3.75183;16.02273834;0.220401085
70.7;2.83588;3.76545;16.04539365;0.220907189
70.8;2.83722;3.77812;16.06824979;0.221353686
70.9;2.83855;3.80059;16.09096566;0.222374211
71;2.83988;3.80576;16.11371177;0.222380747
71.1;2.8412;3.82398;16.13631678;0.223150637
71.2;2.84253;3.84255;16.15912325;0.223936267
71.3;2.84385;3.8532;16.18178825;0.224260708
71.4;2.84517;3.87035;16.20448318;0.224961713
71.5;2.84649;3.87775;16.2272081;0.225094512
71.6;2.84781;3.90059;16.24996303;0.226121644
71.7;2.84913;3.91037;16.27274801;0.22638957
71.8;2.85044;3.9277;16.29539014;0.227095195
71.9;2.85176;3.9427;16.31823513;0.227661766
72;2.85307;3.95167;16.34093688;0.227880998
72.1;2.85438;3.96903;16.3636684;0.228582458
72.2;2.85569;3.98812;16.38642971;0.229381194
72.3;2.85699;3.99958;16.40904676;0.22974147
72.4;2.8583;4.01668;16.43186756;0.230421668
72.5;2.8596;4.03409;16.45454372;0.231119763
72.6;2.8609;4.04373;16.47724938;0.231371076
72.7;2.8622;4.0557;16.49998458;0.23175449
72.8;2.8635;4.07633;16.52274936;0.232630731
72.9;2.86479;4.08957;16.54536829;0.233085446
73;2.86609;4.10821;16.5681921;0.233843641
73.1;2.86738;4.11887;16.59086969;0.234148173
73.2;2.86867;4.13559;16.61357656;0.234795584
73.3;2.86996;4.15127;16.63631273;0.235381968
73.4;2.87125;4.17069;16.65907826;0.236178239
73.5;2.87254;4.18057;16.68187317;0.23643253
73.6;2.87382;4.1987;16.70452046;0.237154122
73.7;2.8751;4.21201;16.72719675;0.237601582
73.8;2.87639;4.22738;16.75007959;0.238161186
73.9;2.87767;4.24563;16.77281424;0.238883383
74;2.87894;4.25745;16.79540005;0.239244411
74.1;2.88022;4.27496;16.81819275;0.239921077
74.2;2.88149;4.28653;16.84083623;0.240265083
74.3;2.88277;4.30693;16.86368712;0.241099722
74.4;2.88404;4.32209;16.88638842;0.241641292
74.5;2.88531;4.33245;16.90911856;0.241913078
74.6;2.88658;4.34942;16.93187759;0.242552403
74.7;2.88784;4.36465;16.954486;0.243095235
74.8;2.88911;4.37843;16.97730268;0.243553223
74.9;2.89037;4.39701;16.99996836;0.244278763
75;2.89163;4.41269;17.02266261;0.244841181
75.1;2.89289;4.4273;17.04538548;0.245342501
75.2;2.89415;4.43935;17.068137;0.245700484
75.3;2.89541;4.45434;17.0909172;0.246219689
75.4;2.89666;4.47242;17.11354498;0.246910254
75.5;2.89792;4.50026;17.13638243;0.248134379
75.6;2.89917;4.50613;17.15906709;0.24814766
75.7;2.90042;4.51906;17.18178011;0.24854882
75.8;2.90167;4.52837;17.20452155;0.24874974
75.9;2.90292;4.55081;17.22729143;0.249670118
76;2.90416;4.56263;17.24990729;0.250008393
76.1;2.90541;4.58165;17.27273394;0.250736973
76.2;2.90665;4.60082;17.29540618;0.251474056
76.3;2.90789;4.61491;17.31810656;0.251931606
76.4;2.90913;4.626;17.3408351;0.252224066
76.5;2.91037;4.6404;17.36359184;0.252695662
76.6;2.91161;4.6526;17.38637682;0.253046049
76.7;2.91284;4.66788;17.40900597;0.253565022
76.8;2.91408;4.68707;17.4318473;0.254291929
76.9;2.91531;4.70165;17.45453242;0.254769392
77;2.91654;4.71723;17.47724546;0.255299417
77.1;2.91777;4.72794;17.49998646;0.255564511
77.2;2.919;4.74613;17.52275544;0.256232396
77.3;2.92022;4.76023;17.54536699;0.25668028
77.4;2.92145;4.77639;17.56819183;0.257235063
77.5;2.92267;4.78701;17.59085885;0.257492676
77.6;2.92389;4.79763;17.61355353;0.257749279
77.7;2.92511;4.81276;17.63627593;0.258246874
77.8;2.92633;4.8198;17.65902606;0.258309302
77.9;2.92755;4.83188;17.68180396;0.258640975
78;2.92877;4.83901;17.70460967;0.258706815
78.1;2.92998;4.8364;17.72725595;0.2582546
78.2;2.93119;4.84556;17.74992964;0.258430836
78.3;2.93241;4.86914;17.77281852;0.259371814
78.4;2.93362;4.87695;17.79554737;0.259473688
78.5;2.93482;4.90676;17.81811557;0.260746618
78.6;2.93603;4.92;17.84089927;0.261134032
78.7;2.93724;4.94139;17.86371056;0.261952175
78.8;2.93844;4.95554;17.8863606;0.262387238
78.9;2.93964;4.96276;17.90903783;0.262454391
79;2.94084;4.97819;17.9317423;0.262954667
79.1;2.94204;4.99505;17.95447403;0.263528811
79.2;2.94324;5.00312;17.97723305;0.263638012
79.3;2.94444;5.03649;18.0000194;0.26507815
79.4;2.94563;5.04816;18.02264288;0.265376374
79.5;2.94683;5.06036;18.04548375;0.265698686
79.6;2.94802;5.07391;18.06816137;0.266093301
79.7;2.94921;5.09074;18.09086599;0.266658412
79.8;2.9504;5.11454;18.11359764;0.267586464
79.9;2.95159;5.13358;18.13635636;0.26826319
80;2.95278;5.15114;18.15914218;0.26886068
80.1;2.95396;5.16006;18.18176331;0.269008637
80.2;2.95413;5.16993;18.18502449;0.269477373