File: Tensile-Tests-Data/Mold Star 16 FAST.csv
PARAMETER;INFO;;;
Specimen Thickness (mm);3;;;
Specimen Width (mm);6;;;
Specimen Length (mm);33;;;
Specimen Cross-section (cm^2);0.18;;;
Standard;ASTM D412;;;
Type of test;Pull-to-failure;;;
Speed (mm/min);450;;;
Machine;Instron  5569;;;
Load Cell;1 kN - Instron  2525-806;;;
Grippers;Instron 2710-010 ;;;
Strain Measurement;Global;;;
Strain calculation;Derived from the machine crosshead displacement readings;;;
Lab;Univ. Savoie Mont Blanc - SYMME Lab, 7400 Annecy, France;;;
Material supplier;Smooth-On;;;
Material;Mold Star 16 FAST;;;
;;;;
Time (s);True Strain;True Stress (MPa);Engineering Strain;Engineering Stress (MPa)
0.2;0.01829;0.0262408;;
0.3;0.04363;0.00717144;;
0.4;0.06574;0.0137248;;
0.5;0.08695;0.0219165;;
0.6;0.10761;0.0271258;;
0.7;0.12783;0.033414;;
0.8;0.14764;0.0393555;;
0.9;0.16705;0.0452093;;
1;0.1861;0.0516831;;
1.1;0.20479;0.0572511;;
1.2;0.22314;0.0642637;;
1.3;0.24116;0.0701539;;
1.4;0.25886;0.0776447;;
1.5;0.27626;0.0833272;;
1.6;0.29335;0.090393;;
1.7;0.31015;0.0974477;;
1.8;0.32668;0.104271;;
1.9;0.34294;0.11148;;
2;0.35895;0.119103;;
2.1;0.3747;0.126534;;
2.2;0.3902;0.133706;;
2.3;0.40546;0.142034;;
2.4;0.4205;0.149629;;
2.5;0.43532;0.158491;;
2.6;0.44992;0.166719;;
2.7;0.46431;0.175395;;
2.8;0.47849;0.183892;;
2.9;0.49248;0.193466;;
3;0.50627;0.201613;;
3.1;0.51987;0.211538;;
3.2;0.5333;0.221407;;
3.3;0.54654;0.231336;;
3.4;0.55962;0.241459;;
3.5;0.57252;0.252279;;
3.6;0.58526;0.262399;;
3.7;0.59783;0.273763;;
3.8;0.61026;0.28519;;
3.9;0.62253;0.296457;;
4;0.63465;0.308236;;
4.1;0.64663;0.320085;;
4.2;0.65846;0.332078;;
4.3;0.67016;0.344883;;
4.4;0.68172;0.357368;;
4.5;0.69315;0.371002;;
4.6;0.70445;0.383814;;
4.7;0.71562;0.398255;;
4.8;0.72667;0.4124;;
4.9;0.7376;0.427099;;
5;0.74841;0.44206;;
5.1;0.75911;0.457861;;
5.2;0.76969;0.474431;;
5.3;0.78016;0.490828;;
5.4;0.79052;0.507971;;
5.5;0.80078;0.524417;;
5.6;0.81093;0.542129;;
5.7;0.82098;0.559642;;
5.8;0.83093;0.577473;;
5.9;0.84078;0.594917;;
6;0.85054;0.612909;;
6.1;0.8602;0.631092;;
6.2;0.86977;0.649844;;
6.3;0.87925;0.66937;;
6.4;0.88864;0.688703;;
6.5;0.89794;0.709012;;
6.6;0.90716;0.728595;;
6.7;0.91629;0.748786;;
6.8;0.92534;0.770051;;
6.9;0.93431;0.791814;;
7;0.9432;0.813538;;
7.1;0.95201;0.835373;;
7.2;0.96074;0.857681;;
7.3;0.9694;0.879907;;
7.4;0.97798;0.902808;;
7.5;0.98649;0.926271;;
7.6;0.99493;0.950469;;
7.7;1.0033;0.97504;;
7.8;1.0116;0.999402;;
7.9;1.01983;1.02466;;
8;1.02799;1.04961;;
8.1;1.03609;1.07609;;
8.2;1.04412;1.10219;;
8.3;1.05209;1.12953;;
8.4;1.06;1.15637;;
8.5;1.06784;1.18425;;
8.6;1.07562;1.2116;;
8.7;1.08334;1.24081;;
8.8;1.09101;1.27;;
8.9;1.09861;1.299;;
9;1.10616;1.32965;;
9.1;1.11365;1.35916;;
9.2;1.12108;1.38942;;
9.3;1.12846;1.42104;;
9.4;1.13579;1.4524;;
9.5;1.14306;1.48443;;
9.6;1.15029;1.51658;;
9.7;1.15745;1.54949;;
9.8;1.16457;1.58316;;
9.9;1.17164;1.61723;;
10;1.17865;1.65079;;
10.1;1.18562;1.68589;;
10.2;1.19254;1.72197;;
10.3;1.19942;1.75659;;
10.4;1.20624;1.79337;;
10.5;1.21302;1.8288;;
10.6;1.21976;1.86679;;
10.7;1.22645;1.90413;;
10.8;1.23309;1.94211;;
10.9;1.23969;1.98098;;
11;1.24625;2.01955;;
11.1;1.25276;2.05947;;
11.2;1.25923;2.09916;;
11.3;1.26567;2.14014;;
11.4;1.27206;2.18165;;
11.5;1.27841;2.22224;;
11.6;1.28471;2.26438;;
11.7;1.29098;2.30686;;
11.8;1.29721;2.3492;;
11.9;1.30341;2.39275;;
12;1.30956;2.43668;;
12.1;1.31568;2.48201;;
12.2;1.32176;2.52588;;
12.3;1.3278;2.57099;;
12.4;1.3338;2.61732;;
12.5;1.33977;2.66335;;
12.6;1.34571;2.70901;;
12.7;1.35161;2.75786;;
12.8;1.35747;2.80515;;
12.9;1.3633;2.85329;;
13;1.3691;2.90242;;
13.1;1.37487;2.95145;;
13.2;1.3806;3.00095;;
13.3;1.3863;3.05139;;
13.4;1.39196;3.10323;;
13.5;1.39759;3.15403;;
13.6;1.4032;3.20604;;
13.7;1.40877;3.25745;;
13.8;1.41431;3.31027;;
13.9;1.41982;3.36548;;
14;1.4253;3.41915;;
14.1;1.43075;3.47256;;
14.2;1.43617;3.52746;;
14.3;1.44156;3.58231;;
14.4;1.44692;3.63929;;
14.5;1.45225;3.69538;;
14.6;1.45756;3.75173;;
14.7;1.46283;3.80991;;
14.8;1.46808;3.867;;
14.9;1.47331;3.92567;;
15;1.4785;3.98413;;
15.1;1.48367;4.04403;;
15.2;1.48881;4.10442;;
15.3;1.49393;4.16475;;
15.4;1.49901;4.22578;;
15.5;1.50408;4.28789;;
15.6;1.50911;4.3483;;
15.7;1.51413;4.41189;;
15.8;1.51912;4.47488;;
15.9;1.52408;4.53899;;
16;1.52902;4.6012;;
16.1;1.53393;4.66589;;
16.2;1.53882;4.73044;;
16.3;1.54369;4.79748;;
16.4;1.54853;4.86185;;
16.5;1.55335;4.92849;;
16.6;1.55814;4.9947;;
16.7;1.56292;5.06167;;
16.8;1.56767;5.1309;;
16.9;1.5724;5.19846;;
17;1.5771;5.26699;;
17.1;1.58179;5.33609;;
17.2;1.58645;5.4061;;
17.3;1.59109;5.47631;;
17.4;1.59571;5.54615;;
17.5;1.6003;5.61706;;
17.6;1.60488;5.68792;;
17.7;1.60944;5.76051;;
17.8;1.61397;5.83347;;
17.9;1.61849;5.90671;;
18;1.62298;5.98006;;
18.1;1.62746;6.05162;;
18.2;1.63191;6.12678;;
18.3;1.63635;6.20253;;
18.4;1.64076;6.27723;;
18.5;1.64516;6.35194;;
18.6;1.64953;6.42859;;
18.7;1.65389;6.50386;;
18.8;1.65823;6.58154;;
18.9;1.66255;6.65852;;
19;1.66685;6.73618;;
19.1;1.67113;6.81435;;
19.2;1.6754;6.89276;;
19.3;1.67964;6.97183;;
19.4;1.68387;7.05136;;
19.5;1.68808;7.1321;;
19.6;1.69227;7.21155;;
19.7;1.69645;7.29121;;
19.8;1.70061;7.37342;;
19.9;1.70475;7.45553;;
20;1.70887;7.53767;;
20.1;1.71298;7.62073;;
20.2;1.71707;7.70269;;
20.3;1.72114;7.78648;;
20.4;1.7252;7.8706;;
20.5;1.72924;7.95487;;
20.6;1.73326;8.03828;;
20.7;1.73727;8.12136;;
20.8;1.74126;8.2081;;
20.9;1.74524;8.2936;;
21;1.7492;8.37915;;
21.1;1.75314;8.46656;;
21.2;1.75707;8.55151;;
21.3;1.76099;8.63902;;
21.4;1.76489;8.72761;;
21.5;1.76877;8.81495;;
21.6;1.77264;8.90388;;
21.7;1.77649;8.99032;;
21.8;1.78033;9.0805;;
21.9;1.78415;9.1706;;
22;1.78796;9.26031;;
22.1;1.79176;9.35121;;
22.2;1.79554;9.44028;;
22.3;1.79931;9.53361;;
22.4;1.80306;9.62204;;
22.5;1.8068;9.71409;;
22.6;1.81052;9.80651;;
22.7;1.81423;9.89824;;
22.8;1.81793;9.99248;;
22.9;1.82161;10.0828;;
23;1.82528;10.1781;;
23.1;1.82894;10.2725;;
23.2;1.83258;10.3662;;
23.3;1.83621;10.4599;;
23.4;1.83983;10.5551;;
23.5;1.84343;10.6523;;
23.6;1.84702;10.7468;;
23.7;1.8506;10.841;;
23.8;1.85416;10.9376;;
23.9;1.85772;11.0357;;
24;1.86126;11.1322;;
24.1;1.86478;11.2296;;
24.2;1.8683;11.3269;;
24.3;1.8718;11.4251;;
24.4;1.87529;11.524;;
24.5;1.87877;11.6203;;
24.6;1.88224;11.7218;;
24.7;1.88569;11.8198;;
24.8;1.88913;11.9194;;
24.9;1.89256;12.0185;;
25;1.89598;12.1191;;
25.1;1.89939;12.22;;
25.2;1.90279;12.3211;;
25.3;1.90617;12.4213;;
25.4;1.90954;12.5236;;
25.5;1.9129;12.6266;;
25.6;1.91625;12.7276;;
25.7;1.91959;12.8302;;
25.8;1.92292;12.9355;;
25.9;1.92624;13.0384;;
26;1.92954;13.1416;;
26.1;1.93284;13.2436;;
26.2;1.93612;13.3487;;
26.3;1.9394;13.4546;;
26.4;1.94266;13.5595;;
26.5;1.94591;13.6648;;
26.6;1.94915;13.77;;
26.7;1.95238;13.8754;;
26.8;1.9556;13.9824;;
26.9;1.95881;14.0873;;
27;1.96201;14.1949;;
27.1;1.9652;14.3022;;
27.2;1.96838;14.4088;;
27.3;1.97155;14.5178;;
27.4;1.97471;14.6255;;
27.5;1.97786;14.736;;
27.6;1.981;14.8425;;
27.7;1.98413;14.9505;;
27.8;1.98725;15.0609;;
27.9;1.99036;15.1687;;
28;1.99346;15.2809;;
28.1;1.99655;15.3893;;
28.2;1.99964;15.5006;;
28.3;2.00271;15.6133;;
28.4;2.00577;15.7242;;
28.5;2.00882;15.8361;;
28.6;2.01187;15.9483;;
28.7;2.0149;16.0574;;
28.8;2.01793;16.1723;;
28.9;2.02095;16.2859;;
29;2.02395;16.3971;;
29.1;2.02695;16.5089;;
29.2;2.02994;16.6236;;
29.3;2.03292;16.7386;;
29.4;2.03589;16.8539;;
29.5;2.03886;16.9681;;
29.6;2.04181;17.0852;;
29.7;2.04476;17.1976;;
29.8;2.04769;17.3137;;
29.9;2.05062;17.4318;;
30;2.05354;17.5444;;
30.1;2.05645;17.6621;;
30.2;2.05936;17.7793;;
30.3;2.06225;17.8964;;
30.4;2.06513;18.0166;;
30.5;2.06801;18.1332;;
30.6;2.07088;18.2524;;
30.7;2.07374;18.3714;;
30.8;2.0766;18.4915;;
30.9;2.07944;18.6113;;
31;2.08228;18.7298;;
31.1;2.08511;18.8511;;
31.2;2.08793;18.9713;;
31.3;2.09074;19.0904;;
31.4;2.09355;19.2143;;
31.5;2.09634;19.3343;;
31.6;2.09913;19.4558;;
31.7;2.10191;19.5754;;
31.8;2.10469;19.7002;;
31.9;2.10745;19.8217;;
32;2.11021;19.9488;;
32.1;2.11296;20.0709;;
32.2;2.11571;20.1936;;
32.3;2.11844;20.317;;
32.4;2.12117;20.4414;;
32.5;2.12389;20.5653;;
32.6;2.12661;20.6907;;
32.7;2.12931;20.8178;;
32.8;2.13201;20.9434;;
32.9;2.1347;21.0701;;
33;2.13739;21.1984;;
33.1;2.14007;21.3219;;
33.2;2.14274;21.4521;;
33.3;2.1454;21.5817;;
33.4;2.14806;21.7088;;
33.5;2.1507;21.836;;
33.6;2.15335;21.9645;;
33.7;2.15598;22.0935;;
33.8;2.15861;22.2239;;
33.9;2.16123;22.3554;;
34;2.16385;22.4848;;
34.1;2.16645;22.6142;;
34.2;2.16905;22.7458;;
34.3;2.17165;22.8731;;
34.4;2.17423;23.0058;;
34.5;2.17682;23.1375;;
34.6;2.17939;23.2707;;
34.7;2.18196;23.3998;;
34.8;2.18452;23.5368;;
34.9;2.18707;23.6653;;
35;2.18962;23.7972;;
35.1;2.19216;23.9288;;
35.2;2.1947;24.061;;
35.3;2.19722;24.1951;;
35.4;2.19975;24.329;;
35.5;2.20226;24.4638;;
35.6;2.20477;24.5962;;
35.7;2.20728;24.7302;;
35.8;2.20977;24.8645;;
35.9;2.21226;24.9989;;
36;2.21475;25.133;;
36.1;2.21722;25.2641;;
36.2;2.2197;25.3926;;
36.3;2.22216;25.6576;;
36.4;2.22462;25.7968;;
36.5;2.22708;25.9365;;
36.6;2.22953;26.0757;;