File: Tensile-Tests-Data/Mold Star 20T.csv
PARAMETER;INFO;;;
Specimen Thickness (mm);3;;;
Specimen Width (mm);6;;;
Specimen Length (mm);33;;;
Specimen Cross-section (cm^2);0.18;;;
Standard;ASTM D412;;;
Type of test;Pull-to-failure;;;
Speed (mm/min);450;;;
Machine;Instron  5569;;;
Load Cell;1 kN - Instron  2525-806;;;
Grippers;Instron 2710-010 ;;;
Strain Measurement;Global;;;
Strain calculation;Derived from the machine crosshead displacement readings;;;
Lab;Univ. Savoie Mont Blanc - SYMME Lab, 7400 Annecy, France;;;
Material supplier;Smooth-On;;;
Material;Mold Star 20T;;;
;;;;
Time (s);True Strain;True Stress (MPa);Engineering Strain;Engineering Stress (MPa)
0.2;0.01821;0.0272297;;
0.3;0.04364;0.00998885;;
0.4;0.06575;0.0190678;;
0.5;0.08695;0.0284142;;
0.6;0.10762;0.0362191;;
0.7;0.12783;0.0438901;;
0.8;0.14764;0.0518714;;
0.9;0.16705;0.0595301;;
1;0.1861;0.0675674;;
1.1;0.2048;0.0758728;;
1.2;0.22315;0.0844025;;
1.3;0.24117;0.0920614;;
1.4;0.25886;0.101382;;
1.5;0.27625;0.109938;;
1.6;0.29335;0.119024;;
1.7;0.31015;0.127672;;
1.8;0.32669;0.136629;;
1.9;0.34295;0.146168;;
2;0.35895;0.155938;;
2.1;0.37469;0.165933;;
2.2;0.3902;0.175755;;
2.3;0.40546;0.186749;;
2.4;0.4205;0.195631;;
2.5;0.43532;0.206232;;
2.6;0.44992;0.218149;;
2.7;0.46431;0.227701;;
2.8;0.47849;0.240395;;
2.9;0.49247;0.251189;;
3;0.50627;0.263588;;
3.1;0.51988;0.275416;;
3.2;0.5333;0.287661;;
3.3;0.54655;0.300381;;
3.4;0.55962;0.31348;;
3.5;0.57252;0.326713;;
3.6;0.58526;0.340324;;
3.7;0.59784;0.353994;;
3.8;0.61026;0.368328;;
3.9;0.62253;0.383121;;
4;0.63465;0.397598;;
4.1;0.64663;0.41296;;
4.2;0.65846;0.428299;;
4.3;0.67016;0.444989;;
4.4;0.68172;0.460391;;
4.5;0.69315;0.478159;;
4.6;0.70445;0.494843;;
4.7;0.71562;0.511565;;
4.8;0.72667;0.530332;;
4.9;0.7376;0.548242;;
5;0.74841;0.567426;;
5.1;0.75911;0.586495;;
5.2;0.76969;0.605536;;
5.3;0.78016;0.625388;;
5.4;0.79052;0.646043;;
5.5;0.80078;0.666825;;
5.6;0.81093;0.688231;;
5.7;0.82098;0.709226;;
5.8;0.83093;0.73136;;
5.9;0.84078;0.753452;;
6;0.85054;0.777036;;
6.1;0.8602;0.800183;;
6.2;0.86977;0.823466;;
6.3;0.87925;0.847742;;
6.4;0.88864;0.872455;;
6.5;0.89794;0.897455;;
6.6;0.90716;0.922761;;
6.7;0.91629;0.948798;;
6.8;0.92534;0.974829;;
6.9;0.93431;1.00249;;
7;0.9432;1.02935;;
7.1;0.95201;1.05692;;
7.2;0.96074;1.08538;;
7.3;0.9694;1.11443;;
7.4;0.97798;1.14346;;
7.5;0.9865;1.17284;;
7.6;0.99493;1.20312;;
7.7;1.0033;1.23407;;
7.8;1.0116;1.26528;;
7.9;1.01983;1.29639;;
8;1.02799;1.32783;;
8.1;1.03609;1.36132;;
8.2;1.04413;1.39401;;
8.3;1.05209;1.42725;;
8.4;1.06;1.46083;;
8.5;1.06784;1.49564;;
8.6;1.07562;1.53055;;
8.7;1.08335;1.56586;;
8.8;1.09101;1.60165;;
8.9;1.09861;1.63802;;
9;1.10616;1.67522;;
9.1;1.11365;1.71243;;
9.2;1.12109;1.7496;;
9.3;1.12847;1.78863;;
9.4;1.13579;1.82745;;
9.5;1.14307;1.86672;;
9.6;1.15028;1.90676;;
9.7;1.15745;1.94676;;
9.8;1.16457;1.98797;;
9.9;1.17164;2.02904;;
10;1.17866;2.07037;;
10.1;1.18562;2.11271;;
10.2;1.19254;2.15537;;
10.3;1.19942;2.19869;;
10.4;1.20624;2.24329;;
10.5;1.21302;2.28686;;
10.6;1.21976;2.331;;
10.7;1.22645;2.37551;;
10.8;1.23309;2.42264;;
10.9;1.23969;2.46855;;
11;1.24625;2.5166;;
11.1;1.25276;2.56288;;
11.2;1.25924;2.61057;;
11.3;1.26567;2.6592;;
11.4;1.27206;2.70876;;
11.5;1.27841;2.75739;;
11.6;1.28471;2.80689;;
11.7;1.29098;2.85791;;
11.8;1.29722;2.91013;;
11.9;1.30341;2.96127;;
12;1.30956;3.01222;;
12.1;1.31568;3.06495;;
12.2;1.32176;3.11793;;
12.3;1.3278;3.17204;;
12.4;1.3338;3.22593;;
12.5;1.33978;3.28073;;
12.6;1.34571;3.33557;;
12.7;1.35161;3.39225;;
12.8;1.35747;3.44764;;
12.9;1.3633;3.50629;;
13;1.3691;3.56358;;
13.1;1.37487;3.62042;;
13.2;1.3806;3.67876;;
13.3;1.3863;3.73736;;
13.4;1.39196;3.79764;;
13.5;1.39759;3.85872;;
13.6;1.4032;3.91944;;
13.7;1.40877;3.97999;;
13.8;1.41431;4.04271;;
13.9;1.41982;4.10445;;
14;1.4253;4.16653;;
14.1;1.43075;4.23164;;
14.2;1.43617;4.29435;;
14.3;1.44156;4.35936;;
14.4;1.44692;4.42533;;
14.5;1.45225;4.49059;;
14.6;1.45756;4.55801;;
14.7;1.46283;4.62428;;
14.8;1.46808;4.69247;;
14.9;1.47331;4.76113;;
15;1.4785;4.82798;;
15.1;1.48367;4.89847;;
15.2;1.48881;4.96658;;
15.3;1.49392;5.03895;;
15.4;1.49901;5.11073;;
15.5;1.50408;5.1814;;
15.6;1.50912;5.25368;;
15.7;1.51413;5.32539;;
15.8;1.51912;5.39936;;
15.9;1.52408;5.47408;;
16;1.52902;5.54855;;
16.1;1.53393;5.62507;;
16.2;1.53882;5.6995;;
16.3;1.54369;5.77672;;
16.4;1.54853;5.85318;;
16.5;1.55335;5.93061;;
16.6;1.55814;6.01014;;
16.7;1.56292;6.08861;;
16.8;1.56767;6.16863;;
16.9;1.5724;6.2485;;
17;1.5771;6.32843;;
17.1;1.58179;6.41157;;
17.2;1.58645;6.49342;;
17.3;1.59109;6.57656;;
17.4;1.59571;6.65967;;
17.5;1.60031;6.74248;;
17.6;1.60488;6.82612;;
17.7;1.60944;6.91227;;
17.8;1.61397;6.99963;;
17.9;1.61849;7.08455;;
18;1.62298;7.17207;;
18.1;1.62746;7.25925;;
18.2;1.63191;7.34771;;
18.3;1.63635;7.43758;;
18.4;1.64076;7.52622;;
18.5;1.64516;7.61712;;
18.6;1.64953;7.70734;;
18.7;1.65389;7.7986;;
18.8;1.65823;7.89192;;
18.9;1.66255;7.98459;;
19;1.66685;8.07867;;
19.1;1.67113;8.17294;;
19.2;1.6754;8.26661;;
19.3;1.67964;8.36372;;
19.4;1.68387;8.46035;;
19.5;1.68808;8.55659;;
19.6;1.69227;8.6542;;
19.7;1.69645;8.75142;;
19.8;1.70061;8.84991;;
19.9;1.70475;8.95106;;
20;1.70887;9.05029;;
20.1;1.71298;9.1514;;
20.2;1.71707;9.25082;;
20.3;1.72114;9.35505;;
20.4;1.7252;9.45756;;
20.5;1.72924;9.56053;;
20.6;1.73326;9.66538;;
20.7;1.73727;9.76936;;
20.8;1.74126;9.8751;;
20.9;1.74524;9.98125;;
21;1.7492;10.0852;;
21.1;1.75315;10.1939;;
21.2;1.75707;10.3009;;
21.3;1.76099;10.4091;;
21.4;1.76489;10.5196;;
21.5;1.76877;10.6292;;
21.6;1.77264;10.7397;;
21.7;1.77649;10.8503;;
21.8;1.78033;10.9626;;
21.9;1.78416;11.0732;;
22;1.78796;11.187;;
22.1;1.79176;11.302;;
22.2;1.79554;11.4147;;
22.3;1.79931;11.5273;;
22.4;1.80306;11.6454;;
22.5;1.8068;11.76;;
22.6;1.81052;11.8774;;
22.7;1.81423;11.9926;;
22.8;1.81793;12.1119;;
22.9;1.82161;12.2311;;
23;1.82528;12.347;;
23.1;1.82894;12.4685;;
23.2;1.83258;12.5867;;
23.3;1.83621;12.7072;;
23.4;1.83983;12.829;;
23.5;1.84343;12.9483;;
23.6;1.84702;13.0711;;
23.7;1.8506;13.1908;;
23.8;1.85417;13.3132;;
23.9;1.85772;13.4357;;
24;1.86126;13.561;;
24.1;1.86478;13.6845;;
24.2;1.8683;13.8098;;
24.3;1.8718;13.9352;;
24.4;1.87529;14.0638;;
24.5;1.87877;14.1877;;
24.6;1.88224;14.3156;;
24.7;1.88569;14.4393;;
24.8;1.88913;14.5675;;
24.9;1.89256;14.6945;;
25;1.89598;14.8224;;
25.1;1.89939;14.9489;;
25.2;1.90279;15.0743;;
25.3;1.90617;15.2022;;
25.4;1.90954;15.3284;;
25.5;1.9129;15.4563;;
25.6;1.91625;15.5854;;
25.7;1.91959;15.7077;;
25.8;1.92292;15.8356;;
25.9;1.92624;15.9573;;
26;1.92954;16.0756;;
26.1;1.93284;16.1921;;
26.2;1.93612;16.307;;
26.3;1.9394;16.4205;;
26.4;1.94266;16.5363;;
26.5;1.94591;16.6533;;
26.6;1.94915;16.7656;;
26.7;1.95238;16.8665;;
26.8;1.9556;16.9681;;
26.9;1.95881;17.0609;;
27;1.96201;17.1508;;
27.1;1.9652;17.2461;;
27.2;1.96838;17.3497;;
27.3;1.97155;17.4572;;
27.4;1.97471;17.5672;;
27.5;1.97786;17.6854;;
27.6;1.981;17.8032;;
27.7;1.98413;17.9217;;
27.8;1.98725;18.046;;
27.9;1.99036;18.1711;;
28;1.99346;18.2896;;
28.1;1.99655;18.4054;;
28.2;1.99964;18.5129;;
28.3;2.00271;18.6159;;
28.4;2.00577;18.7056;;
28.5;2.00882;18.79;;
28.6;2.01187;18.8802;;
28.7;2.0149;18.9712;;
28.8;2.01793;19.0684;;
28.9;2.02095;19.1726;;
29;2.02395;19.2932;;
29.1;2.02695;19.4256;;
29.2;2.02994;19.5623;;
29.3;2.03292;19.7087;;
29.4;2.03589;19.8555;;
29.5;2.03886;20.0048;;
29.6;2.04181;20.157;;
29.7;2.04476;20.3084;;
29.8;2.04769;20.4603;;
29.9;2.05062;20.6108;;
30;2.05354;20.7608;;
30.1;2.05645;20.9122;;
30.2;2.05935;21.062;;
30.3;2.06225;21.2129;;
30.4;2.06514;21.3628;;
30.5;2.06801;21.5152;;
30.6;2.07088;21.6662;;
30.7;2.07374;21.8156;;
30.8;2.0766;21.9689;;
30.9;2.07944;22.1196;;
31;2.08228;22.2692;;
31.1;2.08511;22.4225;;
31.2;2.08793;22.5754;;
31.3;2.09074;22.7296;;
31.4;2.09355;22.8808;;
31.5;2.09634;23.0394;;
31.6;2.09913;23.1915;;
31.7;2.10191;23.3461;;
31.8;2.10469;23.5027;;
31.9;2.10746;23.6589;;
32;2.11021;23.8107;;
32.1;2.11296;23.9662;;
32.2;2.11571;24.1233;;
32.3;2.11844;24.2807;;
32.4;2.12117;24.4383;;
32.5;2.12389;24.5969;;
32.6;2.12661;24.758;;
32.7;2.12931;24.9132;;
32.8;2.13201;25.0772;;
32.9;2.1347;25.2373;;
33;2.13739;25.3976;;
33.1;2.14007;25.5594;;
33.2;2.14274;25.7168;;
33.3;2.1454;25.8823;;
33.4;2.14806;25.9789;;
33.5;2.1507;26.1371;;
33.6;2.15335;26.2989;;
33.7;2.15598;26.4566;;
33.8;2.15861;26.6194;;
33.9;2.16123;26.7789;;
34;2.16385;26.9416;;
34.1;2.16645;27.1085;;
34.2;2.16905;27.2697;;
34.3;2.17165;27.4375;;
34.4;2.17424;27.5987;;
34.5;2.17682;27.7635;;
34.6;2.17939;27.9221;;
34.7;2.18196;28.0842;;
34.8;2.18452;28.2489;;
34.9;2.18707;28.4145;;
35;2.18962;28.5784;;
35.1;2.19216;28.7425;;
35.2;2.1947;28.9005;;
35.3;2.19722;29.0624;;
35.4;2.19975;29.2187;;
35.5;2.20226;29.3661;;
35.6;2.20477;29.5163;;
35.7;2.20728;29.6462;;
35.8;2.20977;29.7591;;
35.9;2.21226;29.836;;
36;2.21475;29.9031;;
36.1;2.21723;29.9648;;
36.2;2.2197;30.0622;;
36.3;2.22216;30.1808;;